<!--GRIPPER-->
<mujoco>
    <body name="UR5:robotiq_85_base_link" pos="0 0.0823 0" quat="0.707107 -0.707107 0 0"> <!pos="0 0.0823 0" quat="0.5 -0.5 0.5 0.5 ">
        <inertial pos="0.00021987 -2.3546e-10 0.030163"  quat="0.707058 0.00723369 0.00723345 0.707081" mass="0.30915" diaginertia="0.00030737 0.000289758 0.000199102" />
        <geom type="mesh" rgba="0.1 0.1 0.1 1" friction="0.8 0.8 0.8" mesh="robotiq_85_base_link_coarse" />


    <body name="UR5:left_inner_knuckle" pos="0.0127 0 0.0693075">
        <inertial pos="0.0170975 -3.93809e-10 0.0224918"   quat="0.947655 0 -0.319297 0" mass="1.10931" diaginertia="5.59353e-06 3.96549e-06 1.88108e-06" />
        <geom type="mesh" rgba="0.1 0.1 0.1 1" friction="0.8 0.8 0.8" mesh="inner_knuckle_coarse" />
        <joint name="UR5:base_to_lik" class="GRIPPER" pos="0 0 0" axis="0 1 0" limited="true" range="-1 1" />

        <body name="UR5:left_inner_finger" pos="0.0345853 0 0.045497" >
            <inertial pos="0.00602756 0 0.00669926"  quat="0.699065 0.106339 0.106339 0.699065" mass=".4" diaginertia="1.70064e-06 1.58577e-06 3.69621e-07" />
            <geom type="mesh" rgba="0.1 0.1 0.1 1" friction="10 0.8 0.8" mesh="inner_finger_coarse" />
        </body>
    </body>

    <body name="UR5:right_inner_knuckle" pos="-0.0127 0 0.0693075" quat="0 0 0 1"> <! mass=0.0110931>
        <inertial pos="0.0168606 3.93808e-10 0.02267"  quat="0.949317 0 -0.314322 0" mass="1.10931" diaginertia="5.59353e-06 3.96549e-06 1.88108e-06" />
        <geom type="mesh" rgba="0.1 0.1 0.1 1" friction="1 0.8 0.8" mesh="inner_knuckle_coarse" />
        <joint name="UR5:base_to_rik" class="GRIPPER" pos="0 0 0" axis="0 1 0" limited="true" range="-1 1" /> <!range="-1 1">

        <body name="UR5:right_inner_finger" pos="0.034106 0 0.0458574">
            <inertial pos="0.00602756 0 0.00669926"  quat="0.699065 0.106339 0.106339 0.699065" mass=".4" diaginertia="1.70064e-06 1.58577e-06 3.69621e-07" />
            <geom type="mesh" rgba="0.1 0.1 0.1 1" friction="10 0.8 0.8" mesh="inner_finger_coarse" /><!mass= 0.00724255>
        </body>
    </body>  
    
    </body>

</mujoco>
           